# js 中的错误处理

[你不知道的前端异常处理（万字长文，建议收藏）](https://mp.weixin.qq.com/s?__biz=MzA3MjU5NjU2NA==&mid=2455503622&idx=1&sn=6a4a598803d02f4e233fd57ff540b6af&chksm=88b34e3dbfc4c72b7ad3b9ba79154b3f11d055a09492b2cfd6b7cf42d0be784ae2719bc06029&scene=21#wechat_redirect)

## 1. try-catch

try-catch 是错误处理中经常使用的一种方式，但是他只能处理同步代码，是无法捕捉异步代码

try catch 的作用仅仅是捕获当前调用栈的错误。因此异步的错误是无法捕获的。


-   处理同步代码举例（正确事例）

```javascript
function add(a, b) {
    return a * b;
}
try {
    add(1);
} catch (e) {
    console.log("e", e);
    // 这里会捕获到：  e  ReferenceError: c is not defined
}
```

-   试图捕获异步代码举例（错误事例）

```javascript
function handleAsyncThing() {
    setTimeout(() => {
        throw Error("你抓不到我，哈哈哈");
    }, 0);
}

try {
    handleAsyncThing();
} catch (e) {
    console.log("e", e);
    //不会执行这里的逻辑， 在浏览器环境中会报： ‘Uncaught Error: 你抓不到我，哈哈哈’
}
```
- try-catch 可以捕获 await 抛出的错误

本质上这只是一个语法糖，是 Promise.prototype.catch 的一个语法糖而已。而这一语法糖能够成立的原因在于其用了 Promise 这种包装类型。如果你不用包装类型，比如上面的 fs.readFile 不用 Promise 等包装类型包装，打死都不能用 try catch 捕获。

```js
function p1(){
     return new Promise(()=>{
        throw new Error('this is a error')
    })
}
async function fn(){
    try{
        await p1()
     }catch(e){
         console.log('e',e)
     }
}
fn()

```

## error-first（错误优先） 错误处理风格

-   在上面代码，将 test 中的回调函数的第一个参数设置为错误信息，如果有错误就处理，没有错误就把第一个位置的参数设置为 null
-   如果留意的话，这在很多库里都是这么实现的

```javascript
function test(cb) {
    setTimeout(() => {
        try {
            const res = (function (a, b) {
                return a + b + c;
            })(1, 2);
            console.log("try");

            cb(null, res);
        } catch (e) {
            console.log("e", e);
            cb(e);
        }
    }, 0);
}

test((err, res) => {
    if (err) {
        console.log("err", err);
    } else {
        console.log("res", res);
    }
});
```
